<mujoco model="assembly scene">
  <!-- <option gravity="0 0 0"></option> -->

  <compiler angle="radian" meshdir="assets/"/>

  <option timestep="0.005" integrator="implicitfast" iterations="5" ls_iterations="8">
    <flag eulerdamp="disable"/>
  </option>

  <size nkey="1"/>

  <visual>
    <global azimuth="120" elevation="-20"/>
    <headlight ambient="0.3 0.3 0.3" diffuse="0.6 0.6 0.6" specular="0 0 0"/>
    <scale forcewidth="0.05" contactwidth="0.075" contactheight="0.025" com="0.05" framelength="0.2" framewidth="0.01"/>
    <rgba haze="0.15 0.25 0.35 1"/>
  </visual>

  <statistic extent="1" center="0.3 0 0.4"/>

  <default>
    <default class="panda">
      <material shininess="0.25"/>
      <joint range="-2.8973 2.8973" armature="0.1" damping="1"/>
      <general ctrlrange="-2.8973 2.8973" forcerange="-100 100" biastype="affine" biasprm="0 -1"/>
      <default class="finger">
        <joint type="slide" range="0 0.04"/>
      </default>
      <default class="visual">
        <geom type="mesh" contype="0" conaffinity="0" group="2"/>
      </default>
      <default class="collision">
        <geom type="mesh" contype="0" conaffinity="0" group="3"/>
        <default class="primitive_collision">
          <geom type="box" solref="0.01" solimp="0.99 0.995 0.01"/>
          <default class="fingertip_pad_collision_1">
            <geom size="0.011 0.0075 0.01"/>
          </default>
          <default class="fingertip_pad_collision_2">
            <geom size="0.011 0.0044 0.0019"/>
          </default>
          <default class="fingertip_pad_collision_3">
            <geom size="0.00875 0.0035 0.01175"/>
          </default>
          <default class="fingertip_pad_collision_4">
            <geom size="0.00875 0.0076 0.00825" conaffinity="3"/>
          </default>
        </default>
      </default>
    </default>
    <default class="peg">
      <geom size="0.01 0.01 0.01" type="mesh" contype="0" conaffinity="0" group="2"/>
    </default>
    <default class="peg_collision">
      <geom type="box" group="3"/>
    </default>
  </default>

  <custom>
    <numeric name="max_contact_points" size="1" data="12"/>
  </custom>

  <asset>
    <texture type="skybox" builtin="gradient" rgb1="0.3 0.5 0.7" rgb2="0 0 0" width="512" height="3072"/>
    <texture type="2d" name="groundplane" builtin="checker" mark="edge" rgb1="0.2 0.3 0.4" rgb2="0.1 0.2 0.3" markrgb="0.8 0.8 0.8" width="300" height="300"/>
    <material name="white" class="panda"/>
    <material name="off_white" class="panda" rgba="0.901961 0.921569 0.929412 1"/>
    <material name="black" class="panda" rgba="0.25 0.25 0.25 1"/>
    <material name="green" class="panda" rgba="0 1 0 1"/>
    <material name="light_blue" class="panda" rgba="0.039216 0.541176 0.780392 1"/>
    <material name="groundplane" texture="groundplane" texuniform="true" texrepeat="5 5" reflectance="0.2"/>
    <mesh name="link0_c" file="link0.stl"/>
    <mesh name="link1_c" file="link1.stl"/>
    <mesh name="link2_c" file="link2.stl"/>
    <mesh name="link3_c" file="link3.stl"/>
    <mesh name="link4_c" file="link4.stl"/>
    <mesh name="link5_c0" file="link5_collision_0.obj"/>
    <mesh name="link5_c1" file="link5_collision_1.obj"/>
    <mesh name="link5_c2" file="link5_collision_2.obj"/>
    <mesh name="link6_c" file="link6.stl"/>
    <mesh name="link7_c" file="link7.stl"/>
    <mesh name="hand_c" file="hand.stl"/>
    <mesh name="link0_0" file="link0_0.obj"/>
    <mesh name="link0_1" file="link0_1.obj"/>
    <mesh name="link0_2" file="link0_2.obj"/>
    <mesh name="link0_3" file="link0_3.obj"/>
    <mesh name="link0_4" file="link0_4.obj"/>
    <mesh name="link0_5" file="link0_5.obj"/>
    <mesh name="link0_7" file="link0_7.obj"/>
    <mesh name="link0_8" file="link0_8.obj"/>
    <mesh name="link0_9" file="link0_9.obj"/>
    <mesh name="link0_10" file="link0_10.obj"/>
    <mesh name="link0_11" file="link0_11.obj"/>
    <mesh name="link1" file="link1.obj"/>
    <mesh name="link2" file="link2.obj"/>
    <mesh name="link3_0" file="link3_0.obj"/>
    <mesh name="link3_1" file="link3_1.obj"/>
    <mesh name="link3_2" file="link3_2.obj"/>
    <mesh name="link3_3" file="link3_3.obj"/>
    <mesh name="link4_0" file="link4_0.obj"/>
    <mesh name="link4_1" file="link4_1.obj"/>
    <mesh name="link4_2" file="link4_2.obj"/>
    <mesh name="link4_3" file="link4_3.obj"/>
    <mesh name="link5_0" file="link5_0.obj"/>
    <mesh name="link5_1" file="link5_1.obj"/>
    <mesh name="link5_2" file="link5_2.obj"/>
    <mesh name="link6_0" file="link6_0.obj"/>
    <mesh name="link6_1" file="link6_1.obj"/>
    <mesh name="link6_2" file="link6_2.obj"/>
    <mesh name="link6_3" file="link6_3.obj"/>
    <mesh name="link6_4" file="link6_4.obj"/>
    <mesh name="link6_5" file="link6_5.obj"/>
    <mesh name="link6_6" file="link6_6.obj"/>
    <mesh name="link6_7" file="link6_7.obj"/>
    <mesh name="link6_8" file="link6_8.obj"/>
    <mesh name="link6_9" file="link6_9.obj"/>
    <mesh name="link6_10" file="link6_10.obj"/>
    <mesh name="link6_11" file="link6_11.obj"/>
    <mesh name="link6_12" file="link6_12.obj"/>
    <mesh name="link6_13" file="link6_13.obj"/>
    <mesh name="link6_14" file="link6_14.obj"/>
    <mesh name="link6_15" file="link6_15.obj"/>
    <mesh name="link6_16" file="link6_16.obj"/>
    <mesh name="link7_0" file="link7_0.obj"/>
    <mesh name="link7_1" file="link7_1.obj"/>
    <mesh name="link7_2" file="link7_2.obj"/>
    <mesh name="link7_3" file="link7_3.obj"/>
    <mesh name="link7_4" file="link7_4.obj"/>
    <mesh name="link7_5" file="link7_5.obj"/>
    <mesh name="link7_6" file="link7_6.obj"/>
    <mesh name="link7_7" file="link7_7.obj"/>
    <mesh name="hand_0" file="hand_0.obj"/>
    <mesh name="hand_1" file="hand_1.obj"/>
    <mesh name="hand_2" file="hand_2.obj"/>
    <mesh name="hand_3" file="hand_3.obj"/>
    <mesh name="hand_4" file="hand_4.obj"/>
    <mesh name="finger_0" file="finger_0.obj"/>
    <mesh name="finger_1" file="finger_1.obj"/>
    <mesh name="hole2d" file="hole2d/hole2d.obj" scale="0.05 0.05 0.05"/>
    <mesh name="hole2d_collision_0" file="hole2d/hole2d_collision_0.obj" scale="0.05 0.05 0.05"/>
    <mesh name="hole2d_collision_1" file="hole2d/hole2d_collision_1.obj" scale="0.05 0.05 0.05"/>
    <mesh name="hole2d_collision_2" file="hole2d/hole2d_collision_2.obj" scale="0.05 0.05 0.05"/>
  </asset>

  <worldbody>
    <geom name="floor" size="0 0 0.05" type="plane" material="groundplane"/>
    <light name="top" pos="0 0 2" dir="0 0 -1" mode="trackcom"/>
    <light pos="0 0 1.5" dir="0 0 -1" directional="true"/>
    <body name="link0" childclass="panda">
      <inertial pos="-0.041018 -0.00014 0.049974" quat="0.00630474 0.751245 0.00741774 0.659952" mass="0.629769" diaginertia="0.00430465 0.00387984 0.00313051"/>
      <geom class="visual" material="off_white" mesh="link0_0"/>
      <geom class="visual" material="black" mesh="link0_1"/>
      <geom class="visual" material="off_white" mesh="link0_2"/>
      <geom class="visual" material="black" mesh="link0_3"/>
      <geom class="visual" material="off_white" mesh="link0_4"/>
      <geom class="visual" material="black" mesh="link0_5"/>
      <geom class="visual" material="white" mesh="link0_7"/>
      <geom class="visual" material="white" mesh="link0_8"/>
      <geom class="visual" material="black" mesh="link0_9"/>
      <geom class="visual" material="off_white" mesh="link0_10"/>
      <geom class="visual" material="white" mesh="link0_11"/>
      <geom class="collision" mesh="link0_c"/>
      <body name="link1" pos="0 0 0.333">
        <inertial pos="0.003875 0.002081 -0.04762" quat="0.711549 0.00634377 -0.0131124 0.702485" mass="4.97068" diaginertia="0.707137 0.703435 0.00852456"/>
        <joint name="joint1" pos="0 0 0" axis="0 0 1" damping="40"/>
        <geom class="visual" material="white" mesh="link1"/>
        <geom class="collision" mesh="link1_c"/>
        <body name="link2" quat="0.707107 -0.707107 0 0">
          <inertial pos="-0.003141 -0.02872 0.003495" quat="-0.168175 0.828366 -0.122878 0.520027" mass="0.646926" diaginertia="0.0310326 0.0283001 0.00273425"/>
          <joint name="joint2" pos="0 0 0" axis="0 0 1" range="-1.7628 1.7628" damping="40"/>
          <geom class="visual" material="white" mesh="link2"/>
          <geom class="collision" mesh="link2_c"/>
          <body name="link3" pos="0 -0.316 0" quat="0.707107 0.707107 0 0">
            <inertial pos="0.027518 0.039252 -0.066502" quat="0.662769 -0.00678331 0.252053 0.705096" mass="3.2286" diaginertia="0.0415014 0.0414793 0.00124635"/>
            <joint name="joint3" pos="0 0 0" axis="0 0 1" damping="40"/>
            <geom class="visual" material="white" mesh="link3_0"/>
            <geom class="visual" material="white" mesh="link3_1"/>
            <geom class="visual" material="white" mesh="link3_2"/>
            <geom class="visual" material="black" mesh="link3_3"/>
            <geom class="collision" mesh="link3_c"/>
            <body name="link4" pos="0.0825 0 0" quat="0.707107 0.707107 0 0">
              <inertial pos="-0.05317 0.104419 0.027454" quat="0.65058 0.529822 -0.0962034 0.535518" mass="3.5879" diaginertia="0.0349596 0.0281483 0.0106201"/>
              <joint name="joint4" pos="0 0 0" axis="0 0 1" range="-3.0718 -0.0698" damping="40"/>
              <geom class="visual" material="white" mesh="link4_0"/>
              <geom class="visual" material="white" mesh="link4_1"/>
              <geom class="visual" material="black" mesh="link4_2"/>
              <geom class="visual" material="white" mesh="link4_3"/>
              <geom class="collision" mesh="link4_c"/>
              <body name="link5" pos="-0.0825 0.384 0" quat="0.707107 -0.707107 0 0">
                <inertial pos="-0.011953 0.041065 -0.038437" quat="0.987313 -0.0121954 0.0719187 -0.141037" mass="1.22595" diaginertia="0.0367625 0.0288531 0.00803437"/>
                <joint name="joint5" pos="0 0 0" axis="0 0 1" damping="2"/>
                <geom class="visual" material="black" mesh="link5_0"/>
                <geom class="visual" material="white" mesh="link5_1"/>
                <geom class="visual" material="white" mesh="link5_2"/>
                <geom class="collision" mesh="link5_c0"/>
                <geom class="collision" mesh="link5_c1"/>
                <geom class="collision" mesh="link5_c2"/>
                <body name="link6" quat="0.707107 0.707107 0 0">
                  <inertial pos="0.060149 -0.014117 -0.010517" quat="0.101075 0.59332 0.0287227 0.798079" mass="1.66656" diaginertia="0.00584276 0.00431037 0.00159787"/>
                  <joint name="joint6" pos="0 0 0" axis="0 0 1" range="-0.0175 3.7525" damping="2"/>
                  <geom class="visual" material="off_white" mesh="link6_0"/>
                  <geom class="visual" material="white" mesh="link6_1"/>
                  <geom class="visual" material="black" mesh="link6_2"/>
                  <geom class="visual" material="white" mesh="link6_3"/>
                  <geom class="visual" material="white" mesh="link6_4"/>
                  <geom class="visual" material="white" mesh="link6_5"/>
                  <geom class="visual" material="white" mesh="link6_6"/>
                  <geom class="visual" material="light_blue" mesh="link6_7"/>
                  <geom class="visual" material="light_blue" mesh="link6_8"/>
                  <geom class="visual" material="black" mesh="link6_9"/>
                  <geom class="visual" material="black" mesh="link6_10"/>
                  <geom class="visual" material="white" mesh="link6_11"/>
                  <geom class="visual" material="green" mesh="link6_12"/>
                  <geom class="visual" material="white" mesh="link6_13"/>
                  <geom class="visual" material="black" mesh="link6_14"/>
                  <geom class="visual" material="black" mesh="link6_15"/>
                  <geom class="visual" material="white" mesh="link6_16"/>
                  <geom class="collision" mesh="link6_c"/>
                  <body name="link7" pos="0.088 0 0" quat="0.707107 0.707107 0 0">
                    <inertial pos="0.010517 -0.004252 0.061597" quat="0.992939 -0.0762041 0.0733595 -0.0537067" mass="0.735522" diaginertia="0.0127345 0.0101055 0.00451803"/>
                    <joint name="joint7" pos="0 0 0" axis="0 0 1" damping="2"/>
                    <geom class="visual" material="white" mesh="link7_0"/>
                    <geom class="visual" material="black" mesh="link7_1"/>
                    <geom class="visual" material="black" mesh="link7_2"/>
                    <geom class="visual" material="black" mesh="link7_3"/>
                    <geom class="visual" material="black" mesh="link7_4"/>
                    <geom class="visual" material="black" mesh="link7_5"/>
                    <geom class="visual" material="black" mesh="link7_6"/>
                    <geom class="visual" material="white" mesh="link7_7"/>
                    <geom class="collision" mesh="link7_c"/>
                    <body name="hand" pos="0 0 0.107" quat="0.92388 0 0 -0.382683">
                      <inertial pos="-0.01 0 0.03" mass="0.73" diaginertia="0.001 0.0025 0.0017"/>
                      <geom class="visual" material="off_white" mesh="hand_0"/>
                      <geom class="visual" material="black" mesh="hand_1"/>
                      <geom class="visual" material="black" mesh="hand_2"/>
                      <geom class="visual" material="white" mesh="hand_3"/>
                      <geom class="visual" material="off_white" mesh="hand_4"/>
                      <geom class="collision" mesh="hand_c"/>
                      <geom name="hand_capsule" class="collision" size="0.04 0.06" pos="0 0 0.03" quat="0.707107 0.707107 0 0" type="capsule" conaffinity="1"/>
                      <site name="gripper" pos="0 0 0.1"/>
                      <body name="left_finger" pos="0 0 0.0584">
                        <inertial pos="0 0 0" mass="0.015" diaginertia="2.375e-06 2.375e-06 7.5e-07"/>
                        <joint name="finger_joint1" class="finger" pos="0 0 0" axis="0 1 0" damping="10"/>
                        <geom class="visual" material="off_white" mesh="finger_0"/>
                        <geom class="visual" material="black" mesh="finger_1"/>
                        <geom class="collision" mesh="finger_0"/>
                        <geom class="fingertip_pad_collision_1" pos="0 0.0185 0.011"/>
                        <geom class="fingertip_pad_collision_2" pos="0 0.0068 0.0022"/>
                        <geom class="fingertip_pad_collision_3" pos="0 0.0159 0.02835" quat="0.970143 0.242536 0 0"/>
                        <geom name="left_finger_pad" class="fingertip_pad_collision_4" pos="0 0.00758 0.04525"/>
                      </body>
                      <body name="right_finger" pos="0 0 0.0584" quat="0 0 0 1">
                        <inertial pos="0 0 0" mass="0.015" diaginertia="2.375e-06 2.375e-06 7.5e-07"/>
                        <joint name="finger_joint2" class="finger" pos="0 0 0" axis="0 1 0" damping="10"/>
                        <geom class="visual" material="off_white" mesh="finger_0"/>
                        <geom class="visual" material="black" mesh="finger_1"/>
                        <geom class="collision" mesh="finger_0"/>
                        <geom class="fingertip_pad_collision_1" pos="0 0.0185 0.011"/>
                        <geom class="fingertip_pad_collision_2" pos="0 0.0068 0.0022"/>
                        <geom class="fingertip_pad_collision_3" pos="0 0.0159 0.02835" quat="0.970143 0.242536 0 0"/>
                        <geom name="right_finger_pad" class="fingertip_pad_collision_4" pos="0 0.00758 0.04525"/>
                      </body>
                    </body>
                  </body>
                </body>
              </body>
            </body>
          </body>
        </body>
      </body>
    </body>
    <body name="peg" pos="0.4 0 0.25">
      <joint type="free" limited="false" actuatorfrclimited="false"/>
      <geom name="peg" size="0.025 0.1 0.1" type="box" contype="2" friction="1 0.03 0.003" solref="0.01" rgba="0 1 0 1"/>
    </body>
    <body name="hole" pos="0.4 0 0.1" quat="0.707105 0.707108 0 0">
      <geom name="hole" class="visual" mesh="hole2d"/>
      <geom class="peg_collision" size="0.0500036 0.0999975 0.100009" pos="1.51465e-10 -0.0499941 -5.66566e-11" quat="0.707107 -5.6768e-06 -5.6768e-06 0.707107" rgba="0.76096 0.179196 0.776212 1"/>
      <geom class="peg_collision" size="0.0362187 0.0499864 0.100013" pos="0.0637789 0.0500038 6.40986e-11" rgba="0.345306 0.103829 0.504207 1"/>
      <geom class="peg_collision" size="0.0362187 0.0499864 0.100013" pos="-0.0637789 0.0500038 1.1642e-09" rgba="0.8428 0.505815 0.211787 1"/>
    </body>
    <body name="camera" pos="0 0 0.1">
      <camera name="main" pos="0.3 -1.5 0.4" quat="0.707107 0.707107 0 0" orthographic="true" fovy="1.1"/>
    </body>
    <body pos="0.75 0 0.1">
      <joint type="free" limited="false" actuatorfrclimited="false"/>
      <geom name="peg2" size="0.025 0.1 0.1" type="box" rgba="1 0 0 1"/>
    </body>
  </worldbody>

  <equality>
    <joint joint1="finger_joint1" joint2="finger_joint2" polycoef="0 1 0 0 0" solref="0.005" solimp="0.95 0.99"/>
  </equality>

  <actuator>
    <general name="actuator1" class="panda" joint="joint1" gainprm="1000" biasprm="0 -1000 -20"/>
    <general name="actuator2" class="panda" joint="joint2" ctrlrange="-1.7628 1.7628" gainprm="1000" biasprm="0 -1000 -20"/>
    <general name="actuator3" class="panda" joint="joint3" gainprm="750" biasprm="0 -750 -4"/>
    <general name="actuator4" class="panda" joint="joint4" ctrlrange="-3.0718 -0.0698" gainprm="750" biasprm="0 -750 -4"/>
    <general name="actuator5" class="panda" joint="joint5" forcerange="-12 12" gainprm="300" biasprm="0 -300 -2"/>
    <general name="actuator6" class="panda" joint="joint6" ctrlrange="-0.0175 3.7525" forcerange="-12 12" gainprm="300" biasprm="0 -300 -2"/>
    <general name="actuator7" class="panda" joint="joint7" forcerange="-12 12" gainprm="300" biasprm="0 -300 -2"/>
    <general name="actuator8" class="panda" joint="finger_joint1" ctrlrange="0 0.04" forcerange="-200 200" gainprm="350" biasprm="0 -350 -10"/>
  </actuator>

  <keyframe>
    <key name="home" qpos="0 0.3 0 -1.57079 0 2 -0.7853 0.04 0.04 0.8 0 0.1 1 0 0 0 0.6 0 0.1 1 0 0 0" ctrl="0 0.3 0 -1.57079 0 2 -0.7853 0.04"/>
  </keyframe>
</mujoco>
